Workbook

Sheet Results Input
A1: GenAI SEC RAG — Evaluation Results Input | 100 Questions
A2: QUESTION METADATA | H2: RETRIEVAL | K2: GENERATION | N2: TOKEN MATCH (script) | Q2: AGENTIC / DECISION
A3: Q ID | B3: System | C3: Company | D3: Form | E3: Year | F3: Q Type | G3: Expected Decision | H3: Precision | I3: Recall | J3: Relevancy | K3: Faithfulness | L3: Answer Relevancy | M3: Hallucination (↓ lower) | N3: F1 (Token) | O3: Precision (Token) | P3: Recall (Token) | Q3: Task Completion | R3: Correct Answer (1/0)
A4: 1 | B4: Baseline RAG | C4: Apple | D4: 10-K | E4: 2023 | F4: extractive | G4: ANSWER
A5: 2 | B5: Baseline RAG | C5: Apple | D5: 10-Q | E5: 2025 | F5: extractive | G5: ANSWER
A6: 3 | B6: Baseline RAG | C6: Microsoft | D6: 10-Q | E6: 2023 | F6: extractive | G6: ANSWER
A7: 4 | B7: Baseline RAG | C7: Microsoft | D7: 10-K | E7: 2023 | F7: extractive | G7: ANSWER
A8: 5 | B8: Baseline RAG | C8: NVIDIA | D8: 10-K | E8: 2025 | F8: extractive | G8: ANSWER
A9: 6 | B9: Baseline RAG | C9: NVIDIA | D9: 10-K | E9: 2024 | F9: extractive | G9: ANSWER
A10: 7 | B10: Baseline RAG | C10: NVIDIA | D10: 10-K | E10: 2025 | F10: extractive | G10: ANSWER
A11: 8 | B11: Baseline RAG | C11: JPMorgan Chase | D11: 10-K | E11: 2023 | F11: extractive | G11: ANSWER
A12: 9 | B12: Baseline RAG | C12: JPMorgan Chase | D12: 10-K | E12: 2024 | F12: extractive | G12: ANSWER
A13: 10 | B13: Baseline RAG | C13: Bank of America | D13: 10-Q | E13: 2025 | F13: extractive | G13: ANSWER
A14: 11 | B14: Baseline RAG | C14: Bank of America | D14: 10-K | E14: 2024 | F14: extractive | G14: ANSWER
A15: 12 | B15: Baseline RAG | C15: Berkshire Hathaway | D15: 10-K | E15: 2025 | F15: extractive | G15: ANSWER
... A78: 75 | B78: Baseline RAG | C78: Costco | D78: 10-Q | E78: 2024 | F78: reasoning | G78: ANSWER
A79: 76 | B79: Baseline RAG | C79: Apple | F79: hallucination | G79: REFUSE
A80: 77 | B80: Baseline RAG | C80: Apple | F80: hallucination | G80: REFUSE
A81: 78 | B81: Baseline RAG | C81: Microsoft | F81: hallucination | G81: REFUSE
A82: 79 | B82: Baseline RAG | C82: Microsoft | F82: hallucination | G82: REFUSE
A83: 80 | B83: Baseline RAG | C83: NVIDIA | F83: hallucination | G83: REFUSE
A84: 81 | B84: Baseline RAG | C84: NVIDIA | F84: hallucination | G84: REFUSE
A85: 82 | B85: Baseline RAG | C85: NVIDIA | F85: hallucination | G85: REFUSE
A86: 83 | B86: Baseline RAG | C86: JPMorgan Chase | F86: hallucination | G86: REFUSE
A87: 84 | B87: Baseline RAG | C87: JPMorgan Chase | F87: hallucination | G87: REFUSE
A88: 85 | B88: Baseline RAG | C88: Bank of America | F88: hallucination | G88: REFUSE
A89: 86 | B89: Baseline RAG | C89: Bank of America | F89: hallucination | G89: REFUSE
A90: 87 | B90: Baseline RAG | C90: Berkshire Hathaway | F90: hallucination | G90: REFUSE
... A103: 100 | B103: Baseline RAG | C103: Costco | F103: hallucination | G103: REFUSE
A104: 1 | B104: Adv RAG – Hybrid (BM25+Vector) | C104: Apple | D104: 10-K | E104: 2023 | F104: extractive | G104: ANSWER
A105: 2 | B105: Adv RAG – Hybrid (BM25+Vector) | C105: Apple | D105: 10-Q | E105: 2025 | F105: extractive | G105: ANSWER
A106: 3 | B106: Adv RAG – Hybrid (BM25+Vector) | C106: Microsoft | D106: 10-Q | E106: 2023 | F106: extractive | G106: ANSWER
A107: 4 | B107: Adv RAG – Hybrid (BM25+Vector) | C107: Microsoft | D107: 10-K | E107: 2023 | F107: extractive | G107: ANSWER
A108: 5 | B108: Adv RAG – Hybrid (BM25+Vector) | C108: NVIDIA | D108: 10-K | E108: 2025 | F108: extractive | G108: ANSWER
A109: 6 | B109: Adv RAG – Hybrid (BM25+Vector) | C109: NVIDIA | D109: 10-K | E109: 2024 | F109: extractive | G109: ANSWER
A110: 7 | B110: Adv RAG – Hybrid (BM25+Vector) | C110: NVIDIA | D110: 10-K | E110: 2025 | F110: extractive | G110: ANSWER
A111: 8 | B111: Adv RAG – Hybrid (BM25+Vector) | C111: JPMorgan Chase | D111: 10-K | E111: 2023 | F111: extractive | G111: ANSWER
A112: 9 | B112: Adv RAG – Hybrid (BM25+Vector) | C112: JPMorgan Chase | D112: 10-K | E112: 2024 | F112: extractive | G112: ANSWER
A113: 10 | B113: Adv RAG – Hybrid (BM25+Vector) | C113: Bank of America | D113: 10-Q | E113: 2025 | F113: extractive | G113: ANSWER
A114: 11 | B114: Adv RAG – Hybrid (BM25+Vector) | C114: Bank of America | D114: 10-K | E114: 2024 | F114: extractive | G114: ANSWER
...

Sheet Macro Accuracy & F1 & RAGAS
A1: Macro Accuracy & Macro F1 | Unweighted Average Across 4 Question Types
A2: Macro Accuracy = mean of per-type accuracy. Macro F1 = mean of per-type F1 (token). Correct Answer binary (col R) drives accuracy.
A3: PER-TYPE ACCURACY (Correct Answer Rate)
A4: System | B4: extractive | C4: paraphrased | D4: reasoning | E4: hallucination | F4: Macro Accuracy | G4: Macro F1
A5: Baseline RAG | B5: =IFERROR(AVERAGE('Results Input'!R4,'Results Input'!R5,'Results Input'!R6,'Results Input'!R7,'Results Input'!R8,'Results Input'!R9,'Results Input'!R10,'Results Input'!R11,'Results Input'!R12,'Results Input'!R13,'Results Input'!R14,'Results Input'!R15,'Results Input'!R16,'Results Input'!R17,'Results Input'!R18,'Results Input'!R19,'Results Input'!R20,'Results Input'!R21,'Results Input'!R22,'Results Input'!R23,'Results Input'!R24,'Results Input'!R25,'Results Input'!R26,'Results Input'!R27,'Results Input'!R28),"") | C5: =IFERROR(AVERAGE('Results Input'!R29,'Results Input'!R30,'Results Input'!R31,'Results Input'!R32,'Results Input'!R33,'Results Input'!R34,'Results Input'!R35,'Results Input'!R36,'Results Input'!R37,'Results Input'!R38,'Results Input'!R39,'Results Input'!R40,'Results Input'!R41,'Results Input'!R42,'Results Input'!R43,'Results Input'!R44,'Results Input'!R45,'Results Input'!R46,'Results Input'!R47,'Results Input'!R48,'Results Input'!R49,'Results Input'!R50,'Results Input'!R51,'Results Input'!R52,'Results Input'!R53),"") | D5: =IFERROR(AVERAGE('Results Input'!R54,'Results Input'!R55,'Results Input'!R56,'Results Input'!R57,'Results Input'!R58,'Results Input'!R59,'Results Input'!R60,'Results Input'!R61,'Results Input'!R62,'Results Input'!R63,'Results Input'!R64,'Results Input'!R65,'Results Input'!R66,'Results Input'!R67,'Results Input'!R68,'Results Input'!R69,'Results Input'!R70,'Results Input'!R71,'Results Input'!R72,'Results Input'!R73,'Results Input'!R74,'Results Input'!R75,'Results Input'!R76,'Results Input'!R77,'Results Input'!R78),"") | E5: =IFERROR(AVERAGE('Results Input'!R79,'Results Input'!R80,'Results Input'!R81,'Results Input'!R82,'Results Input'!R83,'Results Input'!R84,'Results Input'!R85,'Results Input'!R86,'Results Input'!R87,'Results Input'!R88,'Results Input'!R89,'Results Input'!R90,'Results Input'!R91,'Results Input'!R92,'Results Input'!R93,'Results Input'!R94,'Results Input'!R95,'Results Input'!R96,'Results Input'!R97,'Results Input'!R98,'Results Input'!R99,'Results Input'!R100,'Results Input'!R101,'Results Input'!R102,'Results Input'!R103),"") | F5: =IFERROR(AVERAGE(B5:E5),"") | G5: =IFERROR((AVERAGE('Results Input'!N4,'Results Input'!N5,'Results Input'!N6,'Results Input'!N7,'Results Input'!N8,'Results Input'!N9,'Results Input'!N10,'Results Input'!N11,'Results Input'!N12,'Results Input'!N13,'Results Input'!N14,'Results Input'!N15,'Results Input'!N16,'Results Input'!N17,'Results Input'!N18,'Results Input'!N19,'Results Input'!N20,'Results Input'!N21,'Results Input'!N22,'Results Input'!N23,'Results Input'!N24,'Results Input'!N25,'Results Input'!N26,'Results Input'!N27,'Results Input'!N28)+AVERAGE('Results Input'!N29,'Results Input'!N30,'Results Input'!N31,'Results Input'!N32,'Results Input'!N33,'Results Input'!N34,'Results Input'!N35,'Results Input'!N36,'Results Input'!N37,'Results Input'!N38,'Results Input'!N39,'Results Input'!N40,'Results Input'!N41,'Results Input'!N42,'Results Input'!N43,'Results Input'!N44,'Results Input'!N45,'Results Input'!N46,'Results Input'!N47,'Results Input'!N48,'Results Input'!N49,'Results Input'!N50,'Results Input'!N51,'Results Input'!N52,'Results Input'!N53)+AVERAGE('Results Input'!N54,'Results Input'!N55,'Results Input'!N56,'Results Input'!N57,'Results Input'!N58,'Results Input'!N59,'Results Input'!N60,'Results Input'!N61,'Results Input'!N62,'Results Input'!N63,'Results Input'!N64,'Results Input'!N65,'Results Input'!N66,'Results Input'!N67,'Results Input'!N68,'Results Input'!N69,'Results Input'!N70,'Results Input'!N71,'Results Input'!N72,'Results Input'!N73,'Results Input'!N74,'Results Input'!N75,'Results Input'!N76,'Results Input'!N77,'Results Input'!N78)+AVERAGE('Results Input'!N79,'Results Input'!N80,'Results Input'!N81,'Results Input'!N82,'Results Input'!N83,'Results Input'!N84,'Results Input'!N85,'Results Input'!N86,'Results Input'!N87,'Results Input'!N88,'Results Input'!N89,'Results Input'!N90,'Results Input'!N91,'Results Input'!N92,'Results Input'!N93,'Results Input'!N94,'Results Input'!N95,'Results Input'!N96,'Results Input'!N97,'Results Input'!N98,'Results Input'!N99,'Results Input'!N100,'Results Input'!N101,'Results Input'!N102,'Results Input'!N103))/4,"")
A6: Adv RAG – Hybrid (BM25+Vector) | B6: =IFERROR(AVERAGE('Results Input'!R104,'Results Input'!R105,'Results Input'!R106,'Results Input'!R107,'Results Input'!R108,'Results Input'!R109,'Results Input'!R110,'Results Input'!R111,'Results Input'!R112,'Results Input'!R113,'Results Input'!R114,'Results Input'!R115,'Results Input'!R116,'Results Input'!R117,'Results Input'!R118,'Results Input'!R119,'Results Input'!R120,'Results Input'!R121,'Results Input'!R122,'Results Input'!R123,'Results Input'!R124,'Results Input'!R125,'Results Input'!R126,'Results Input'!R127,'Results Input'!R128),"") | C6: =IFERROR(AVERAGE('Results Input'!R129,'Results Input'!R130,'Results Input'!R131,'Results Input'!R132,'Results Input'!R133,'Results Input'!R134,'Results Input'!R135,'Results Input'!R136,'Results Input'!R137,'Results Input'!R138,'Results Input'!R139,'Results Input'!R140,'Results Input'!R141,'Results Input'!R142,'Results Input'!R143,'Results Input'!R144,'Results Input'!R145,'Results Input'!R146,'Results Input'!R147,'Results Input'!R148,'Results Input'!R149,'Results Input'!R150,'Results Input'!R151,'Results Input'!R152,'Results Input'!R153),"") | D6: =IFERROR(AVERAGE('Results Input'!R154,'Results Input'!R155,'Results Input'!R156,'Results Input'!R157,'Results Input'!R158,'Results Input'!R159,'Results Input'!R160,'Results Input'!R161,'Results Input'!R162,'Results Input'!R163,'Results Input'!R164,'Results Input'!R165,'Results Input'!R166,'Results Input'!R167,'Results Input'!R168,'Results Input'!R169,'Results Input'!R170,'Results Input'!R171,'Results Input'!R172,'Results Input'!R173,'Results Input'!R174,'Results Input'!R175,'Results Input'!R176,'Results Input'!R177,'Results Input'!R178),"") | E6: =IFERROR(AVERAGE('Results Input'!R179,'Results Input'!R180,'Results Input'!R181,'Results Input'!R182,'Results Input'!R183,'Results Input'!R184,'Results Input'!R185,'Results Input'!R186,'Results Input'!R187,'Results Input'!R188,'Results Input'!R189,'Results Input'!R190,'Results Input'!R191,'Results Input'!R192,'Results Input'!R193,'Results Input'!R194,'Results Input'!R195,'Results Input'!R196,'Results Input'!R197,'Results Input'!R198,'Results Input'!R199,'Results Input'!R200,'Results Input'!R201,'Results Input'!R202,'Results Input'!R203),"") | F6: =IFERROR(AVERAGE(B6:E6),"") | G6: =IFERROR((AVERAGE('Results Input'!N104,'Results Input'!N105,'Results Input'!N106,'Results Input'!N107,'Results Input'!N108,'Results Input'!N109,'Results Input'!N110,'Results Input'!N111,'Results Input'!N112,'Results Input'!N113,'Results Input'!N114,'Results Input'!N115,'Results Input'!N116,'Results Input'!N117,'Results Input'!N118,'Results Input'!N119,'Results Input'!N120,'Results Input'!N121,'Results Input'!N122,'Results Input'!N123,'Results Input'!N124,'Results Input'!N125,'Results Input'!N126,'Results Input'!N127,'Results Input'!N128)+AVERAGE('Results Input'!N129,'Results Input'!N130,'Results Input'!N131,'Results Input'!N132,'Results Input'!N133,'Results Input'!N134,'Results Input'!N135,'Results Input'!N136,'Results Input'!N137,'Results Input'!N138,'Results Input'!N139,'Results Input'!N140,'Results Input'!N141,'Results Input'!N142,'Results Input'!N143,'Results Input'!N144,'Results Input'!N145,'Results Input'!N146,'Results Input'!N147,'Results Input'!N148,'Results Input'!N149,'Results Input'!N150,'Results Input'!N151,'Results Input'!N152,'Results Input'!N153)+AVERAGE('Results Input'!N154,'Results Input'!N155,'Results Input'!N156,'Results Input'!N157,'Results Input'!N158,'Results Input'!N159,'Results Input'!N160,'Results Input'!N161,'Results Input'!N162,'Results Input'!N163,'Results Input'!N164,'Results Input'!N165,'Results Input'!N166,'Results Input'!N167,'Results Input'!N168,'Results Input'!N169,'Results Input'!N170,'Results Input'!N171,'Results Input'!N172,'Results Input'!N173,'Results Input'!N174,'Results Input'!N175,'Results Input'!N176,'Results Input'!N177,'Results Input'!N178)+AVERAGE('Results Input'!N179,'Results Input'!N180,'Results Input'!N181,'Results Input'!N182,'Results Input'!N183,'Results Input'!N184,'Results Input'!N185,'Results Input'!N186,'Results Input'!N187,'Results Input'!N188,'Results Input'!N189,'Results Input'!N190,'Results Input'!N191,'Results Input'!N192,'Results Input'!N193,'Results Input'!N194,'Results Input'!N195,'Results Input'!N196,'Results Input'!N197,'Results Input'!N198,'Results Input'!N199,'Results Input'!N200,'Results Input'!N201,'Results Input'!N202,'Results Input'!N203))/4,"")
A7: Adv RAG +LangGraph | B7: =IFERROR(AVERAGE('Results Input'!R204,'Results Input'!R205,'Results Input'!R206,'Results Input'!R207,'Results Input'!R208,'Results Input'!R209,'Results Input'!R210,'Results Input'!R211,'Results Input'!R212,'Results Input'!R213,'Results Input'!R214,'Results Input'!R215,'Results Input'!R216,'Results Input'!R217,'Results Input'!R218,'Results Input'!R219,'Results Input'!R220,'Results Input'!R221,'Results Input'!R222,'Results Input'!R223,'Results Input'!R224,'Results Input'!R225,'Results Input'!R226,'Results Input'!R227,'Results Input'!R228),"") | C7: =IFERROR(AVERAGE('Results Input'!R229,'Results Input'!R230,'Results Input'!R231,'Results Input'!R232,'Results Input'!R233,'Results Input'!R234,'Results Input'!R235,'Results Input'!R236,'Results Input'!R237,'Results Input'!R238,'Results Input'!R239,'Results Input'!R240,'Results Input'!R241,'Results Input'!R242,'Results Input'!R243,'Results Input'!R244,'Results Input'!R245,'Results Input'!R246,'Results Input'!R247,'Results Input'!R248,'Results Input'!R249,'Results Input'!R250,'Results Input'!R251,'Results Input'!R252,'Results Input'!R253),"") | D7: =IFERROR(AVERAGE('Results Input'!R254,'Results Input'!R255,'Results Input'!R256,'Results Input'!R257,'Results Input'!R258,'Results Input'!R259,'Results Input'!R260,'Results Input'!R261,'Results Input'!R262,'Results Input'!R263,'Results Input'!R264,'Results Input'!R265,'Results Input'!R266,'Results Input'!R267,'Results Input'!R268,'Results Input'!R269,'Results Input'!R270,'Results Input'!R271,'Results Input'!R272,'Results Input'!R273,'Results Input'!R274,'Results Input'!R275,'Results Input'!R276,'Results Input'!R277,'Results Input'!R278),"") | E7: =IFERROR(AVERAGE('Results Input'!R279,'Results Input'!R280,'Results Input'!R281,'Results Input'!R282,'Results Input'!R283,'Results Input'!R284,'Results Input'!R285,'Results Input'!R286,'Results Input'!R287,'Results Input'!R288,'Results Input'!R289,'Results Input'!R290,'Results Input'!R291,'Results Input'!R292,'Results Input'!R293,'Results Input'!R294,'Results Input'!R295,'Results Input'!R296,'Results Input'!R297,'Results Input'!R298,'Results Input'!R299,'Results Input'!R300,'Results Input'!R301,'Results Input'!R302,'Results Input'!R303),"") | F7: =IFERROR(AVERAGE(B7:E7),"") | G7: =IFERROR((AVERAGE('Results Input'!N204,'Results Input'!N205,'Results Input'!N206,'Results Input'!N207,'Results Input'!N208,'Results Input'!N209,'Results Input'!N210,'Results Input'!N211,'Results Input'!N212,'Results Input'!N213,'Results Input'!N214,'Results Input'!N215,'Results Input'!N216,'Results Input'!N217,'Results Input'!N218,'Results Input'!N219,'Results Input'!N220,'Results Input'!N221,'Results Input'!N222,'Results Input'!N223,'Results Input'!N224,'Results Input'!N225,'Results Input'!N226,'Results Input'!N227,'Results Input'!N228)+AVERAGE('Results Input'!N229,'Results Input'!N230,'Results Input'!N231,'Results Input'!N232,'Results Input'!N233,'Results Input'!N234,'Results Input'!N235,'Results Input'!N236,'Results Input'!N237,'Results Input'!N238,'Results Input'!N239,'Results Input'!N240,'Results Input'!N241,'Results Input'!N242,'Results Input'!N243,'Results Input'!N244,'Results Input'!N245,'Results Input'!N246,'Results Input'!N247,'Results Input'!N248,'Results Input'!N249,'Results Input'!N250,'Results Input'!N251,'Results Input'!N252,'Results Input'!N253)+AVERAGE('Results Input'!N254,'Results Input'!N255,'Results Input'!N256,'Results Input'!N257,'Results Input'!N258,'Results Input'!N259,'Results Input'!N260,'Results Input'!N261,'Results Input'!N262,'Results Input'!N263,'Results Input'!N264,'Results Input'!N265,'Results Input'!N266,'Results Input'!N267,'Results Input'!N268,'Results Input'!N269,'Results Input'!N270,'Results Input'!N271,'Results Input'!N272,'Results Input'!N273,'Results Input'!N274,'Results Input'!N275,'Results Input'!N276,'Results Input'!N277,'Results Input'!N278)+AVERAGE('Results Input'!N279,'Results Input'!N280,'Results Input'!N281,'Results Input'!N282,'Results Input'!N283,'Results Input'!N284,'Results Input'!N285,'Results Input'!N286,'Results Input'!N287,'Results Input'!N288,'Results Input'!N289,'Results Input'!N290,'Results Input'!N291,'Results Input'!N292,'Results Input'!N293,'Results Input'!N294,'Results Input'!N295,'Results Input'!N296,'Results Input'!N297,'Results Input'!N298,'Results Input'!N299,'Results Input'!N300,'Results Input'!N301,'Results Input'!N302,'Results Input'!N303))/4,"")
A8: Adv RAG + LlamaIndex | B8: =IFERROR(AVERAGE('Results Input'!R304,'Results Input'!R305,'Results Input'!R306,'Results Input'!R307,'Results Input'!R308,'Results Input'!R309,'Results Input'!R310,'Results Input'!R311,'Results Input'!R312,'Results Input'!R313,'Results Input'!R314,'Results Input'!R315,'Results Input'!R316,'Results Input'!R317,'Results Input'!R318,'Results Input'!R319,'Results Input'!R320,'Results Input'!R321,'Results Input'!R322,'Results Input'!R323,'Results Input'!R324,'Results Input'!R325,'Results Input'!R326,'Results Input'!R327,'Results Input'!R328),"") | C8: =IFERROR(AVERAGE('Results Input'!R329,'Results Input'!R330,'Results Input'!R331,'Results Input'!R332,'Results Input'!R333,'Results Input'!R334,'Results Input'!R335,'Results Input'!R336,'Results Input'!R337,'Results Input'!R338,'Results Input'!R339,'Results Input'!R340,'Results Input'!R341,'Results Input'!R342,'Results Input'!R343,'Results Input'!R344,'Results Input'!R345,'Results Input'!R346,'Results Input'!R347,'Results Input'!R348,'Results Input'!R349,'Results Input'!R350,'Results Input'!R351,'Results Input'!R352,'Results Input'!R353),"") | D8: =IFERROR(AVERAGE('Results Input'!R354,'Results Input'!R355,'Results Input'!R356,'Results Input'!R357,'Results Input'!R358,'Results Input'!R359,'Results Input'!R360,'Results Input'!R361,'Results Input'!R362,'Results Input'!R363,'Results Input'!R364,'Results Input'!R365,'Results Input'!R366,'Results Input'!R367,'Results Input'!R368,'Results Input'!R369,'Results Input'!R370,'Results Input'!R371,'Results Input'!R372,'Results Input'!R373,'Results Input'!R374,'Results Input'!R375,'Results Input'!R376,'Results Input'!R377,'Results Input'!R378),"") | E8: =IFERROR(AVERAGE('Results Input'!R379,'Results Input'!R380,'Results Input'!R381,'Results Input'!R382,'Results Input'!R383,'Results Input'!R384,'Results Input'!R385,'Results Input'!R386,'Results Input'!R387,'Results Input'!R388,'Results Input'!R389,'Results Input'!R390,'Results Input'!R391,'Results Input'!R392,'Results Input'!R393,'Results Input'!R394,'Results Input'!R395,'Results Input'!R396,'Results Input'!R397,'Results Input'!R398,'Results Input'!R399,'Results Input'!R400,'Results Input'!R401,'Results Input'!R402,'Results Input'!R403),"") | F8: =IFERROR(AVERAGE(B8:E8),"") | G8: =IFERROR((AVERAGE('Results Input'!N304,'Results Input'!N305,'Results Input'!N306,'Results Input'!N307,'Results Input'!N308,'Results Input'!N309,'Results Input'!N310,'Results Input'!N311,'Results Input'!N312,'Results Input'!N313,'Results Input'!N314,'Results Input'!N315,'Results Input'!N316,'Results Input'!N317,'Results Input'!N318,'Results Input'!N319,'Results Input'!N320,'Results Input'!N321,'Results Input'!N322,'Results Input'!N323,'Results Input'!N324,'Results Input'!N325,'Results Input'!N326,'Results Input'!N327,'Results Input'!N328)+AVERAGE('Results Input'!N329,'Results Input'!N330,'Results Input'!N331,'Results Input'!N332,'Results Input'!N333,'Results Input'!N334,'Results Input'!N335,'Results Input'!N336,'Results Input'!N337,'Results Input'!N338,'Results Input'!N339,'Results Input'!N340,'Results Input'!N341,'Results Input'!N342,'Results Input'!N343,'Results Input'!N344,'Results Input'!N345,'Results Input'!N346,'Results Input'!N347,'Results Input'!N348,'Results Input'!N349,'Results Input'!N350,'Results Input'!N351,'Results Input'!N352,'Results Input'!N353)+AVERAGE('Results Input'!N354,'Results Input'!N355,'Results Input'!N356,'Results Input'!N357,'Results Input'!N358,'Results Input'!N359,'Results Input'!N360,'Results Input'!N361,'Results Input'!N362,'Results Input'!N363,'Results Input'!N364,'Results Input'!N365,'Results Input'!N366,'Results Input'!N367,'Results Input'!N368,'Results Input'!N369,'Results Input'!N370,'Results Input'!N371,'Results Input'!N372,'Results Input'!N373,'Results Input'!N374,'Results Input'!N375,'Results Input'!N376,'Results Input'!N377,'Results Input'!N378)+AVERAGE('Results Input'!N379,'Results Input'!N380,'Results Input'!N381,'Results Input'!N382,'Results Input'!N383,'Results Input'!N384,'Results Input'!N385,'Results Input'!N386,'Results Input'!N387,'Results Input'!N388,'Results Input'!N389,'Results Input'!N390,'Results Input'!N391,'Results Input'!N392,'Results Input'!N393,'Results Input'!N394,'Results Input'!N395,'Results Input'!N396,'Results Input'!N397,'Results Input'!N398,'Results Input'!N399,'Results Input'!N400,'Results Input'!N401,'Results Input'!N402,'Results Input'!N403))/4,"")
A11: How to interpret these metrics
A12: Extractive accuracy | B12: Did the system find and return the exact figure/fact from the filing?
A13: Paraphrased accuracy | B13: Did the system answer correctly even when the question is reworded vs the source text?v( should be the same answer as level 1 extractive question )
A14: Reasoning accuracy | B14: Did the system correctly perform multi-step inference (e.g. compare two segments)?
A15: Hallucination accuracy | B15: Did the system correctly REFUSE when context is insufficient? (expected_decision = REFUSE)
A16: Macro Accuracy | B16: Unweighted mean across all 4 types — treats each type equally regardless of sample size
A17: Macro F1 (Token) | B17: Unweighted mean of per-type token F1 — penalises both missed tokens (recall) and extra tokens (precision)
A20: Evaluating RAG using RAGAS
A21: System | B21: extractive | C21: paraphrased | D21: reasoning | E21: hallucination | F21: Macro Accuracy | G21: Macro F1
A22: Baseline RAG | B22: =IFERROR(AVERAGE('Results Input'!R21,'Results Input'!R22,'Results Input'!R23,'Results Input'!R24,'Results Input'!R25,'Results Input'!R26,'Results Input'!R27,'Results Input'!R28,'Results Input'!R29,'Results Input'!R30,'Results Input'!R31,'Results Input'!R32,'Results Input'!R33,'Results Input'!R34,'Results Input'!R35,'Results Input'!R36,'Results Input'!R37,'Results Input'!R38,'Results Input'!R39,'Results Input'!R40,'Results Input'!R41,'Results Input'!R42,'Results Input'!R43,'Results Input'!R44,'Results Input'!R45),"") | C22: =IFERROR(AVERAGE('Results Input'!R46,'Results Input'!R47,'Results Input'!R48,'Results Input'!R49,'Results Input'!R50,'Results Input'!R51,'Results Input'!R52,'Results Input'!R53,'Results Input'!R54,'Results Input'!R55,'Results Input'!R56,'Results Input'!R57,'Results Input'!R58,'Results Input'!R59,'Results Input'!R60,'Results Input'!R61,'Results Input'!R62,'Results Input'!R63,'Results Input'!R64,'Results Input'!R65,'Results Input'!R66,'Results Input'!R67,'Results Input'!R68,'Results Input'!R69,'Results Input'!R70),"") | D22: =IFERROR(AVERAGE('Results Input'!R71,'Results Input'!R72,'Results Input'!R73,'Results Input'!R74,'Results Input'!R75,'Results Input'!R76,'Results Input'!R77,'Results Input'!R78,'Results Input'!R79,'Results Input'!R80,'Results Input'!R81,'Results Input'!R82,'Results Input'!R83,'Results Input'!R84,'Results Input'!R85,'Results Input'!R86,'Results Input'!R87,'Results Input'!R88,'Results Input'!R89,'Results Input'!R90,'Results Input'!R91,'Results Input'!R92,'Results Input'!R93,'Results Input'!R94,'Results Input'!R95),"") | E22: =IFERROR(AVERAGE('Results Input'!R96,'Results Input'!R97,'Results Input'!R98,'Results Input'!R99,'Results Input'!R100,'Results Input'!R101,'Results Input'!R102,'Results Input'!R103,'Results Input'!R104,'Results Input'!R105,'Results Input'!R106,'Results Input'!R107,'Results Input'!R108,'Results Input'!R109,'Results Input'!R110,'Results Input'!R111,'Results Input'!R112,'Results Input'!R113,'Results Input'!R114,'Results Input'!R115,'Results Input'!R116,'Results Input'!R117,'Results Input'!R118,'Results Input'!R119,'Results Input'!R120),"") | F22: =IFERROR(AVERAGE(B22:E22),"") | G22: =IFERROR((AVERAGE('Results Input'!N21,'Results Input'!N22,'Results Input'!N23,'Results Input'!N24,'Results Input'!N25,'Results Input'!N26,'Results Input'!N27,'Results Input'!N28,'Results Input'!N29,'Results Input'!N30,'Results Input'!N31,'Results Input'!N32,'Results Input'!N33,'Results Input'!N34,'Results Input'!N35,'Results Input'!N36,'Results Input'!N37,'Results Input'!N38,'Results Input'!N39,'Results Input'!N40,'Results Input'!N41,'Results Input'!N42,'Results Input'!N43,'Results Input'!N44,'Results Input'!N45)+AVERAGE('Results Input'!N46,'Results Input'!N47,'Results Input'!N48,'Results Input'!N49,'Results Input'!N50,'Results Input'!N51,'Results Input'!N52,'Results Input'!N53,'Results Input'!N54,'Results Input'!N55,'Results Input'!N56,'Results Input'!N57,'Results Input'!N58,'Results Input'!N59,'Results Input'!N60,'Results Input'!N61,'Results Input'!N62,'Results Input'!N63,'Results Input'!N64,'Results Input'!N65,'Results Input'!N66,'Results Input'!N67,'Results Input'!N68,'Results Input'!N69,'Results Input'!N70)+AVERAGE('Results Input'!N71,'Results Input'!N72,'Results Input'!N73,'Results Input'!N74,'Results Input'!N75,'Results Input'!N76,'Results Input'!N77,'Results Input'!N78,'Results Input'!N79,'Results Input'!N80,'Results Input'!N81,'Results Input'!N82,'Results Input'!N83,'Results Input'!N84,'Results Input'!N85,'Results Input'!N86,'Results Input'!N87,'Results Input'!N88,'Results Input'!N89,'Results Input'!N90,'Results Input'!N91,'Results Input'!N92,'Results Input'!N93,'Results Input'!N94,'Results Input'!N95)+AVERAGE('Results Input'!N96,'Results Input'!N97,'Results Input'!N98,'Results Input'!N99,'Results Input'!N100,'Results Input'!N101,'Results Input'!N102,'Results Input'!N103,'Results Input'!N104,'Results Input'!N105,'Results Input'!N106,'Results Input'!N107,'Results Input'!N108,'Results Input'!N109,'Results Input'!N110,'Results Input'!N111,'Results Input'!N112,'Results Input'!N113,'Results Input'!N114,'Results Input'!N115,'Results Input'!N116,'Results Input'!N117,'Results Input'!N118,'Results Input'!N119,'Results Input'!N120))/4,"")
A23: Adv RAG – Hybrid (BM25+Vector) | B23: =IFERROR(AVERAGE('Results Input'!R121,'Results Input'!R122,'Results Input'!R123,'Results Input'!R124,'Results Input'!R125,'Results Input'!R126,'Results Input'!R127,'Results Input'!R128,'Results Input'!R129,'Results Input'!R130,'Results Input'!R131,'Results Input'!R132,'Results Input'!R133,'Results Input'!R134,'Results Input'!R135,'Results Input'!R136,'Results Input'!R137,'Results Input'!R138,'Results Input'!R139,'Results Input'!R140,'Results Input'!R141,'Results Input'!R142,'Results Input'!R143,'Results Input'!R144,'Results Input'!R145),"") | C23: =IFERROR(AVERAGE('Results Input'!R146,'Results Input'!R147,'Results Input'!R148,'Results Input'!R149,'Results Input'!R150,'Results Input'!R151,'Results Input'!R152,'Results Input'!R153,'Results Input'!R154,'Results Input'!R155,'Results Input'!R156,'Results Input'!R157,'Results Input'!R158,'Results Input'!R159,'Results Input'!R160,'Results Input'!R161,'Results Input'!R162,'Results Input'!R163,'Results Input'!R164,'Results Input'!R165,'Results Input'!R166,'Results Input'!R167,'Results Input'!R168,'Results Input'!R169,'Results Input'!R170),"") | D23: =IFERROR(AVERAGE('Results Input'!R171,'Results Input'!R172,'Results Input'!R173,'Results Input'!R174,'Results Input'!R175,'Results Input'!R176,'Results Input'!R177,'Results Input'!R178,'Results Input'!R179,'Results Input'!R180,'Results Input'!R181,'Results Input'!R182,'Results Input'!R183,'Results Input'!R184,'Results Input'!R185,'Results Input'!R186,'Results Input'!R187,'Results Input'!R188,'Results Input'!R189,'Results Input'!R190,'Results Input'!R191,'Results Input'!R192,'Results Input'!R193,'Results Input'!R194,'Results Input'!R195),"") | E23: =IFERROR(AVERAGE('Results Input'!R196,'Results Input'!R197,'Results Input'!R198,'Results Input'!R199,'Results Input'!R200,'Results Input'!R201,'Results Input'!R202,'Results Input'!R203,'Results Input'!R204,'Results Input'!R205,'Results Input'!R206,'Results Input'!R207,'Results Input'!R208,'Results Input'!R209,'Results Input'!R210,'Results Input'!R211,'Results Input'!R212,'Results Input'!R213,'Results Input'!R214,'Results Input'!R215,'Results Input'!R216,'Results Input'!R217,'Results Input'!R218,'Results Input'!R219,'Results Input'!R220),"") | F23: =IFERROR(AVERAGE(B23:E23),"") | G23: =IFERROR((AVERAGE('Results Input'!N121,'Results Input'!N122,'Results Input'!N123,'Results Input'!N124,'Results Input'!N125,'Results Input'!N126,'Results Input'!N127,'Results Input'!N128,'Results Input'!N129,'Results Input'!N130,'Results Input'!N131,'Results Input'!N132,'Results Input'!N133,'Results Input'!N134,'Results Input'!N135,'Results Input'!N136,'Results Input'!N137,'Results Input'!N138,'Results Input'!N139,'Results Input'!N140,'Results Input'!N141,'Results Input'!N142,'Results Input'!N143,'Results Input'!N144,'Results Input'!N145)+AVERAGE('Results Input'!N146,'Results Input'!N147,'Results Input'!N148,'Results Input'!N149,'Results Input'!N150,'Results Input'!N151,'Results Input'!N152,'Results Input'!N153,'Results Input'!N154,'Results Input'!N155,'Results Input'!N156,'Results Input'!N157,'Results Input'!N158,'Results Input'!N159,'Results Input'!N160,'Results Input'!N161,'Results Input'!N162,'Results Input'!N163,'Results Input'!N164,'Results Input'!N165,'Results Input'!N166,'Results Input'!N167,'Results Input'!N168,'Results Input'!N169,'Results Input'!N170)+AVERAGE('Results Input'!N171,'Results Input'!N172,'Results Input'!N173,'Results Input'!N174,'Results Input'!N175,'Results Input'!N176,'Results Input'!N177,'Results Input'!N178,'Results Input'!N179,'Results Input'!N180,'Results Input'!N181,'Results Input'!N182,'Results Input'!N183,'Results Input'!N184,'Results Input'!N185,'Results Input'!N186,'Results Input'!N187,'Results Input'!N188,'Results Input'!N189,'Results Input'!N190,'Results Input'!N191,'Results Input'!N192,'Results Input'!N193,'Results Input'!N194,'Results Input'!N195)+AVERAGE('Results Input'!N196,'Results Input'!N197,'Results Input'!N198,'Results Input'!N199,'Results Input'!N200,'Results Input'!N201,'Results Input'!N202,'Results Input'!N203,'Results Input'!N204,'Results Input'!N205,'Results Input'!N206,'Results Input'!N207,'Results Input'!N208,'Results Input'!N209,'Results Input'!N210,'Results Input'!N211,'Results Input'!N212,'Results Input'!N213,'Results Input'!N214,'Results Input'!N215,'Results Input'!N216,'Results Input'!N217,'Results Input'!N218,'Results Input'!N219,'Results Input'!N220))/4,"")
A24: Adv RAG +LangGraph | B24: =IFERROR(AVERAGE('Results Input'!R221,'Results Input'!R222,'Results Input'!R223,'Results Input'!R224,'Results Input'!R225,'Results Input'!R226,'Results Input'!R227,'Results Input'!R228,'Results Input'!R229,'Results Input'!R230,'Results Input'!R231,'Results Input'!R232,'Results Input'!R233,'Results Input'!R234,'Results Input'!R235,'Results Input'!R236,'Results Input'!R237,'Results Input'!R238,'Results Input'!R239,'Results Input'!R240,'Results Input'!R241,'Results Input'!R242,'Results Input'!R243,'Results Input'!R244,'Results Input'!R245),"") | C24: =IFERROR(AVERAGE('Results Input'!R246,'Results Input'!R247,'Results Input'!R248,'Results Input'!R249,'Results Input'!R250,'Results Input'!R251,'Results Input'!R252,'Results Input'!R253,'Results Input'!R254,'Results Input'!R255,'Results Input'!R256,'Results Input'!R257,'Results Input'!R258,'Results Input'!R259,'Results Input'!R260,'Results Input'!R261,'Results Input'!R262,'Results Input'!R263,'Results Input'!R264,'Results Input'!R265,'Results Input'!R266,'Results Input'!R267,'Results Input'!R268,'Results Input'!R269,'Results Input'!R270),"") | D24: =IFERROR(AVERAGE('Results Input'!R271,'Results Input'!R272,'Results Input'!R273,'Results Input'!R274,'Results Input'!R275,'Results Input'!R276,'Results Input'!R277,'Results Input'!R278,'Results Input'!R279,'Results Input'!R280,'Results Input'!R281,'Results Input'!R282,'Results Input'!R283,'Results Input'!R284,'Results Input'!R285,'Results Input'!R286,'Results Input'!R287,'Results Input'!R288,'Results Input'!R289,'Results Input'!R290,'Results Input'!R291,'Results Input'!R292,'Results Input'!R293,'Results Input'!R294,'Results Input'!R295),"") | E24: =IFERROR(AVERAGE('Results Input'!R296,'Results Input'!R297,'Results Input'!R298,'Results Input'!R299,'Results Input'!R300,'Results Input'!R301,'Results Input'!R302,'Results Input'!R303,'Results Input'!R304,'Results Input'!R305,'Results Input'!R306,'Results Input'!R307,'Results Input'!R308,'Results Input'!R309,'Results Input'!R310,'Results Input'!R311,'Results Input'!R312,'Results Input'!R313,'Results Input'!R314,'Results Input'!R315,'Results Input'!R316,'Results Input'!R317,'Results Input'!R318,'Results Input'!R319,'Results Input'!R320),"") | F24: =IFERROR(AVERAGE(B24:E24),"") | G24: =IFERROR((AVERAGE('Results Input'!N221,'Results Input'!N222,'Results Input'!N223,'Results Input'!N224,'Results Input'!N225,'Results Input'!N226,'Results Input'!N227,'Results Input'!N228,'Results Input'!N229,'Results Input'!N230,'Results Input'!N231,'Results Input'!N232,'Results Input'!N233,'Results Input'!N234,'Results Input'!N235,'Results Input'!N236,'Results Input'!N237,'Results Input'!N238,'Results Input'!N239,'Results Input'!N240,'Results Input'!N241,'Results Input'!N242,'Results Input'!N243,'Results Input'!N244,'Results Input'!N245)+AVERAGE('Results Input'!N246,'Results Input'!N247,'Results Input'!N248,'Results Input'!N249,'Results Input'!N250,'Results Input'!N251,'Results Input'!N252,'Results Input'!N253,'Results Input'!N254,'Results Input'!N255,'Results Input'!N256,'Results Input'!N257,'Results Input'!N258,'Results Input'!N259,'Results Input'!N260,'Results Input'!N261,'Results Input'!N262,'Results Input'!N263,'Results Input'!N264,'Results Input'!N265,'Results Input'!N266,'Results Input'!N267,'Results Input'!N268,'Results Input'!N269,'Results Input'!N270)+AVERAGE('Results Input'!N271,'Results Input'!N272,'Results Input'!N273,'Results Input'!N274,'Results Input'!N275,'Results Input'!N276,'Results Input'!N277,'Results Input'!N278,'Results Input'!N279,'Results Input'!N280,'Results Input'!N281,'Results Input'!N282,'Results Input'!N283,'Results Input'!N284,'Results Input'!N285,'Results Input'!N286,'Results Input'!N287,'Results Input'!N288,'Results Input'!N289,'Results Input'!N290,'Results Input'!N291,'Results Input'!N292,'Results Input'!N293,'Results Input'!N294,'Results Input'!N295)+AVERAGE('Results Input'!N296,'Results Input'!N297,'Results Input'!N298,'Results Input'!N299,'Results Input'!N300,'Results Input'!N301,'Results Input'!N302,'Results Input'!N303,'Results Input'!N304,'Results Input'!N305,'Results Input'!N306,'Results Input'!N307,'Results Input'!N308,'Results Input'!N309,'Results Input'!N310,'Results Input'!N311,'Results Input'!N312,'Results Input'!N313,'Results Input'!N314,'Results Input'!N315,'Results Input'!N316,'Results Input'!N317,'Results Input'!N318,'Results Input'!N319,'Results Input'!N320))/4,"")
A25: Adv RAG + LlamaIndex | B25: =IFERROR(AVERAGE('Results Input'!R321,'Results Input'!R322,'Results Input'!R323,'Results Input'!R324,'Results Input'!R325,'Results Input'!R326,'Results Input'!R327,'Results Input'!R328,'Results Input'!R329,'Results Input'!R330,'Results Input'!R331,'Results Input'!R332,'Results Input'!R333,'Results Input'!R334,'Results Input'!R335,'Results Input'!R336,'Results Input'!R337,'Results Input'!R338,'Results Input'!R339,'Results Input'!R340,'Results Input'!R341,'Results Input'!R342,'Results Input'!R343,'Results Input'!R344,'Results Input'!R345),"") | C25: =IFERROR(AVERAGE('Results Input'!R346,'Results Input'!R347,'Results Input'!R348,'Results Input'!R349,'Results Input'!R350,'Results Input'!R351,'Results Input'!R352,'Results Input'!R353,'Results Input'!R354,'Results Input'!R355,'Results Input'!R356,'Results Input'!R357,'Results Input'!R358,'Results Input'!R359,'Results Input'!R360,'Results Input'!R361,'Results Input'!R362,'Results Input'!R363,'Results Input'!R364,'Results Input'!R365,'Results Input'!R366,'Results Input'!R367,'Results Input'!R368,'Results Input'!R369,'Results Input'!R370),"") | D25: =IFERROR(AVERAGE('Results Input'!R371,'Results Input'!R372,'Results Input'!R373,'Results Input'!R374,'Results Input'!R375,'Results Input'!R376,'Results Input'!R377,'Results Input'!R378,'Results Input'!R379,'Results Input'!R380,'Results Input'!R381,'Results Input'!R382,'Results Input'!R383,'Results Input'!R384,'Results Input'!R385,'Results Input'!R386,'Results Input'!R387,'Results Input'!R388,'Results Input'!R389,'Results Input'!R390,'Results Input'!R391,'Results Input'!R392,'Results Input'!R393,'Results Input'!R394,'Results Input'!R395),"") | E25: =IFERROR(AVERAGE('Results Input'!R396,'Results Input'!R397,'Results Input'!R398,'Results Input'!R399,'Results Input'!R400,'Results Input'!R401,'Results Input'!R402,'Results Input'!R403,'Results Input'!R404,'Results Input'!R405,'Results Input'!R406,'Results Input'!R407,'Results Input'!R408,'Results Input'!R409,'Results Input'!R410,'Results Input'!R411,'Results Input'!R412,'Results Input'!R413,'Results Input'!R414,'Results Input'!R415,'Results Input'!R416,'Results Input'!R417,'Results Input'!R418,'Results Input'!R419,'Results Input'!R420),"") | F25: =IFERROR(AVERAGE(B25:E25),"") | G25: =IFERROR((AVERAGE('Results Input'!N321,'Results Input'!N322,'Results Input'!N323,'Results Input'!N324,'Results Input'!N325,'Results Input'!N326,'Results Input'!N327,'Results Input'!N328,'Results Input'!N329,'Results Input'!N330,'Results Input'!N331,'Results Input'!N332,'Results Input'!N333,'Results Input'!N334,'Results Input'!N335,'Results Input'!N336,'Results Input'!N337,'Results Input'!N338,'Results Input'!N339,'Results Input'!N340,'Results Input'!N341,'Results Input'!N342,'Results Input'!N343,'Results Input'!N344,'Results Input'!N345)+AVERAGE('Results Input'!N346,'Results Input'!N347,'Results Input'!N348,'Results Input'!N349,'Results Input'!N350,'Results Input'!N351,'Results Input'!N352,'Results Input'!N353,'Results Input'!N354,'Results Input'!N355,'Results Input'!N356,'Results Input'!N357,'Results Input'!N358,'Results Input'!N359,'Results Input'!N360,'Results Input'!N361,'Results Input'!N362,'Results Input'!N363,'Results Input'!N364,'Results Input'!N365,'Results Input'!N366,'Results Input'!N367,'Results Input'!N368,'Results Input'!N369,'Results Input'!N370)+AVERAGE('Results Input'!N371,'Results Input'!N372,'Results Input'!N373,'Results Input'!N374,'Results Input'!N375,'Results Input'!N376,'Results Input'!N377,'Results Input'!N378,'Results Input'!N379,'Results Input'!N380,'Results Input'!N381,'Results Input'!N382,'Results Input'!N383,'Results Input'!N384,'Results Input'!N385,'Results Input'!N386,'Results Input'!N387,'Results Input'!N388,'Results Input'!N389,'Results Input'!N390,'Results Input'!N391,'Results Input'!N392,'Results Input'!N393,'Results Input'!N394,'Results Input'!N395)+AVERAGE('Results Input'!N396,'Results Input'!N397,'Results Input'!N398,'Results Input'!N399,'Results Input'!N400,'Results Input'!N401,'Results Input'!N402,'Results Input'!N403,'Results Input'!N404,'Results Input'!N405,'Results Input'!N406,'Results Input'!N407,'Results Input'!N408,'Results Input'!N409,'Results Input'!N410,'Results Input'!N411,'Results Input'!N412,'Results Input'!N413,'Results Input'!N414,'Results Input'!N415,'Results Input'!N416,'Results Input'!N417,'Results Input'!N418,'Results Input'!N419,'Results Input'!N420))/4,"")

Sheet Metrics Summary
A1: Metrics Summary — Aggregated per System
B2: RETRIEVAL | F2: GENERATION | I2: TOKEN MATCH | L2: AGENTIC | N2: COMPOSITE
A3: System | B3: Precision | C3: Recall | D3: Latency | E3: Relevancy | F3: Faithfulness | G3: Ans Relevancy | H3: Hallucination | I3: F1 (Token) | J3: Precision | K3: Recall (Token) | L3: Task Completion | M3: Accuracy | N3: Composite Score | O3: Rank
A4: Baseline RAG | B4: =IFERROR(AVERAGE('Results Input'!H4:H103),"") | C4: =IFERROR(AVERAGE('Results Input'!I4:I103),"") | E4: =IFERROR(AVERAGE('Results Input'!J4:J103),"") | F4: =IFERROR(AVERAGE('Results Input'!K4:K103),"") | G4: =IFERROR(AVERAGE('Results Input'!L4:L103),"") | H4: =IFERROR(AVERAGE('Results Input'!M4:M103),"") | I4: =IFERROR(AVERAGE('Results Input'!N4:N103),"") | J4: =IFERROR(AVERAGE('Results Input'!O4:O103),"") | K4: =IFERROR(AVERAGE('Results Input'!P4:P103),"") | L4: =IFERROR(AVERAGE('Results Input'!Q4:Q103),"") | M4: =IFERROR(AVERAGE('Results Input'!R4:R103),"")
A5: Adv RAG – Hybrid (BM25+Vector) | B5: =IFERROR(AVERAGE('Results Input'!H104:H203),"") | C5: =IFERROR(AVERAGE('Results Input'!I104:I203),"") | E5: =IFERROR(AVERAGE('Results Input'!J104:J203),"") | F5: =IFERROR(AVERAGE('Results Input'!K104:K203),"") | G5: =IFERROR(AVERAGE('Results Input'!L104:L203),"") | H5: =IFERROR(AVERAGE('Results Input'!M104:M203),"") | I5: =IFERROR(AVERAGE('Results Input'!N104:N203),"") | J5: =IFERROR(AVERAGE('Results Input'!O104:O203),"") | K5: =IFERROR(AVERAGE('Results Input'!P104:P203),"") | L5: =IFERROR(AVERAGE('Results Input'!Q104:Q203),"") | M5: =IFERROR(AVERAGE('Results Input'!R104:R203),"")
A6: Adv RAG +LangGraph | B6: =IFERROR(AVERAGE('Results Input'!H204:H303),"") | C6: =IFERROR(AVERAGE('Results Input'!I204:I303),"") | E6: =IFERROR(AVERAGE('Results Input'!J204:J303),"") | F6: =IFERROR(AVERAGE('Results Input'!K204:K303),"") | G6: =IFERROR(AVERAGE('Results Input'!L204:L303),"") | H6: =IFERROR(AVERAGE('Results Input'!M204:M303),"") | I6: =IFERROR(AVERAGE('Results Input'!N204:N303),"") | J6: =IFERROR(AVERAGE('Results Input'!O204:O303),"") | K6: =IFERROR(AVERAGE('Results Input'!P204:P303),"") | L6: =IFERROR(AVERAGE('Results Input'!Q204:Q303),"") | M6: =IFERROR(AVERAGE('Results Input'!R204:R303),"")
A7: Adv RAG + LlamaIndex | B7: =IFERROR(AVERAGE('Results Input'!H304:H403),"") | C7: =IFERROR(AVERAGE('Results Input'!I304:I403),"") | E7: =IFERROR(AVERAGE('Results Input'!J304:J403),"") | F7: =IFERROR(AVERAGE('Results Input'!K304:K403),"") | G7: =IFERROR(AVERAGE('Results Input'!L304:L403),"") | H7: =IFERROR(AVERAGE('Results Input'!M304:M403),"") | I7: =IFERROR(AVERAGE('Results Input'!N304:N403),"") | J7: =IFERROR(AVERAGE('Results Input'!O304:O403),"") | K7: =IFERROR(AVERAGE('Results Input'!P304:P403),"") | L7: =IFERROR(AVERAGE('Results Input'!Q304:Q403),"") | M7: =IFERROR(AVERAGE('Results Input'!R304:R403),"")
B8: =IFERROR(AVERAGE('Results Input'!H404:H503),"") | C8: =IFERROR(AVERAGE('Results Input'!I404:I503),"") | E8: =IFERROR(AVERAGE('Results Input'!J404:J503),"") | F8: =IFERROR(AVERAGE('Results Input'!K404:K503),"") | G8: =IFERROR(AVERAGE('Results Input'!L404:L503),"") | H8: =IFERROR(AVERAGE('Results Input'!M404:M503),"") | I8: =IFERROR(AVERAGE('Results Input'!N404:N503),"") | J8: =IFERROR(AVERAGE('Results Input'!O404:O503),"") | K8: =IFERROR(AVERAGE('Results Input'!P404:P503),"") | L8: =IFERROR(AVERAGE('Results Input'!Q404:Q503),"") | M8: =IFERROR(AVERAGE('Results Input'!R404:R503),"")

Sheet By Question Type
A1: Performance Breakdown by Question Type | Extractive · Paraphrased · Reasoning · Hallucination
A2: Each cell = AVERAGE of that metric for that system × question type. Fill Results Input first. Hallucination type = REFUSE questions — Task Completion = correct refusal rate.
A3: EXTRACTIVE (25 questions — form 10-K & 10-Q)
A4: System | B4: Faithfulness | C4: Ans Relevancy | D4: Hallucination↓ | E4: F1 Token | F4: Task Completion | G4: Accuracy
A5: Baseline RAG | B5: =IFERROR(AVERAGE('Results Input'!K4,'Results Input'!K5,'Results Input'!K6,'Results Input'!K7,'Results Input'!K8,'Results Input'!K9,'Results Input'!K10,'Results Input'!K11,'Results Input'!K12,'Results Input'!K13,'Results Input'!K14,'Results Input'!K15,'Results Input'!K16,'Results Input'!K17,'Results Input'!K18,'Results Input'!K19,'Results Input'!K20,'Results Input'!K21,'Results Input'!K22,'Results Input'!K23,'Results Input'!K24,'Results Input'!K25,'Results Input'!K26,'Results Input'!K27,'Results Input'!K28),"") | C5: =IFERROR(AVERAGE('Results Input'!L4,'Results Input'!L5,'Results Input'!L6,'Results Input'!L7,'Results Input'!L8,'Results Input'!L9,'Results Input'!L10,'Results Input'!L11,'Results Input'!L12,'Results Input'!L13,'Results Input'!L14,'Results Input'!L15,'Results Input'!L16,'Results Input'!L17,'Results Input'!L18,'Results Input'!L19,'Results Input'!L20,'Results Input'!L21,'Results Input'!L22,'Results Input'!L23,'Results Input'!L24,'Results Input'!L25,'Results Input'!L26,'Results Input'!L27,'Results Input'!L28),"") | D5: =IFERROR(AVERAGE('Results Input'!M4,'Results Input'!M5,'Results Input'!M6,'Results Input'!M7,'Results Input'!M8,'Results Input'!M9,'Results Input'!M10,'Results Input'!M11,'Results Input'!M12,'Results Input'!M13,'Results Input'!M14,'Results Input'!M15,'Results Input'!M16,'Results Input'!M17,'Results Input'!M18,'Results Input'!M19,'Results Input'!M20,'Results Input'!M21,'Results Input'!M22,'Results Input'!M23,'Results Input'!M24,'Results Input'!M25,'Results Input'!M26,'Results Input'!M27,'Results Input'!M28),"") | E5: =IFERROR(AVERAGE('Results Input'!N4,'Results Input'!N5,'Results Input'!N6,'Results Input'!N7,'Results Input'!N8,'Results Input'!N9,'Results Input'!N10,'Results Input'!N11,'Results Input'!N12,'Results Input'!N13,'Results Input'!N14,'Results Input'!N15,'Results Input'!N16,'Results Input'!N17,'Results Input'!N18,'Results Input'!N19,'Results Input'!N20,'Results Input'!N21,'Results Input'!N22,'Results Input'!N23,'Results Input'!N24,'Results Input'!N25,'Results Input'!N26,'Results Input'!N27,'Results Input'!N28),"") | F5: =IFERROR(AVERAGE('Results Input'!Q4,'Results Input'!Q5,'Results Input'!Q6,'Results Input'!Q7,'Results Input'!Q8,'Results Input'!Q9,'Results Input'!Q10,'Results Input'!Q11,'Results Input'!Q12,'Results Input'!Q13,'Results Input'!Q14,'Results Input'!Q15,'Results Input'!Q16,'Results Input'!Q17,'Results Input'!Q18,'Results Input'!Q19,'Results Input'!Q20,'Results Input'!Q21,'Results Input'!Q22,'Results Input'!Q23,'Results Input'!Q24,'Results Input'!Q25,'Results Input'!Q26,'Results Input'!Q27,'Results Input'!Q28),"") | G5: =IFERROR(AVERAGE('Results Input'!R4,'Results Input'!R5,'Results Input'!R6,'Results Input'!R7,'Results Input'!R8,'Results Input'!R9,'Results Input'!R10,'Results Input'!R11,'Results Input'!R12,'Results Input'!R13,'Results Input'!R14,'Results Input'!R15,'Results Input'!R16,'Results Input'!R17,'Results Input'!R18,'Results Input'!R19,'Results Input'!R20,'Results Input'!R21,'Results Input'!R22,'Results Input'!R23,'Results Input'!R24,'Results Input'!R25,'Results Input'!R26,'Results Input'!R27,'Results Input'!R28),"")
A6: Adv RAG – Hybrid (BM25+Vector) | B6: =IFERROR(AVERAGE('Results Input'!K104,'Results Input'!K105,'Results Input'!K106,'Results Input'!K107,'Results Input'!K108,'Results Input'!K109,'Results Input'!K110,'Results Input'!K111,'Results Input'!K112,'Results Input'!K113,'Results Input'!K114,'Results Input'!K115,'Results Input'!K116,'Results Input'!K117,'Results Input'!K118,'Results Input'!K119,'Results Input'!K120,'Results Input'!K121,'Results Input'!K122,'Results Input'!K123,'Results Input'!K124,'Results Input'!K125,'Results Input'!K126,'Results Input'!K127,'Results Input'!K128),"") | C6: =IFERROR(AVERAGE('Results Input'!L104,'Results Input'!L105,'Results Input'!L106,'Results Input'!L107,'Results Input'!L108,'Results Input'!L109,'Results Input'!L110,'Results Input'!L111,'Results Input'!L112,'Results Input'!L113,'Results Input'!L114,'Results Input'!L115,'Results Input'!L116,'Results Input'!L117,'Results Input'!L118,'Results Input'!L119,'Results Input'!L120,'Results Input'!L121,'Results Input'!L122,'Results Input'!L123,'Results Input'!L124,'Results Input'!L125,'Results Input'!L126,'Results Input'!L127,'Results Input'!L128),"") | D6: =IFERROR(AVERAGE('Results Input'!M104,'Results Input'!M105,'Results Input'!M106,'Results Input'!M107,'Results Input'!M108,'Results Input'!M109,'Results Input'!M110,'Results Input'!M111,'Results Input'!M112,'Results Input'!M113,'Results Input'!M114,'Results Input'!M115,'Results Input'!M116,'Results Input'!M117,'Results Input'!M118,'Results Input'!M119,'Results Input'!M120,'Results Input'!M121,'Results Input'!M122,'Results Input'!M123,'Results Input'!M124,'Results Input'!M125,'Results Input'!M126,'Results Input'!M127,'Results Input'!M128),"") | E6: =IFERROR(AVERAGE('Results Input'!N104,'Results Input'!N105,'Results Input'!N106,'Results Input'!N107,'Results Input'!N108,'Results Input'!N109,'Results Input'!N110,'Results Input'!N111,'Results Input'!N112,'Results Input'!N113,'Results Input'!N114,'Results Input'!N115,'Results Input'!N116,'Results Input'!N117,'Results Input'!N118,'Results Input'!N119,'Results Input'!N120,'Results Input'!N121,'Results Input'!N122,'Results Input'!N123,'Results Input'!N124,'Results Input'!N125,'Results Input'!N126,'Results Input'!N127,'Results Input'!N128),"") | F6: =IFERROR(AVERAGE('Results Input'!Q104,'Results Input'!Q105,'Results Input'!Q106,'Results Input'!Q107,'Results Input'!Q108,'Results Input'!Q109,'Results Input'!Q110,'Results Input'!Q111,'Results Input'!Q112,'Results Input'!Q113,'Results Input'!Q114,'Results Input'!Q115,'Results Input'!Q116,'Results Input'!Q117,'Results Input'!Q118,'Results Input'!Q119,'Results Input'!Q120,'Results Input'!Q121,'Results Input'!Q122,'Results Input'!Q123,'Results Input'!Q124,'Results Input'!Q125,'Results Input'!Q126,'Results Input'!Q127,'Results Input'!Q128),"") | G6: =IFERROR(AVERAGE('Results Input'!R104,'Results Input'!R105,'Results Input'!R106,'Results Input'!R107,'Results Input'!R108,'Results Input'!R109,'Results Input'!R110,'Results Input'!R111,'Results Input'!R112,'Results Input'!R113,'Results Input'!R114,'Results Input'!R115,'Results Input'!R116,'Results Input'!R117,'Results Input'!R118,'Results Input'!R119,'Results Input'!R120,'Results Input'!R121,'Results Input'!R122,'Results Input'!R123,'Results Input'!R124,'Results Input'!R125,'Results Input'!R126,'Results Input'!R127,'Results Input'!R128),"")
A7: Adv RAG +LangGraph | B7: =IFERROR(AVERAGE('Results Input'!K204,'Results Input'!K205,'Results Input'!K206,'Results Input'!K207,'Results Input'!K208,'Results Input'!K209,'Results Input'!K210,'Results Input'!K211,'Results Input'!K212,'Results Input'!K213,'Results Input'!K214,'Results Input'!K215,'Results Input'!K216,'Results Input'!K217,'Results Input'!K218,'Results Input'!K219,'Results Input'!K220,'Results Input'!K221,'Results Input'!K222,'Results Input'!K223,'Results Input'!K224,'Results Input'!K225,'Results Input'!K226,'Results Input'!K227,'Results Input'!K228),"") | C7: =IFERROR(AVERAGE('Results Input'!L204,'Results Input'!L205,'Results Input'!L206,'Results Input'!L207,'Results Input'!L208,'Results Input'!L209,'Results Input'!L210,'Results Input'!L211,'Results Input'!L212,'Results Input'!L213,'Results Input'!L214,'Results Input'!L215,'Results Input'!L216,'Results Input'!L217,'Results Input'!L218,'Results Input'!L219,'Results Input'!L220,'Results Input'!L221,'Results Input'!L222,'Results Input'!L223,'Results Input'!L224,'Results Input'!L225,'Results Input'!L226,'Results Input'!L227,'Results Input'!L228),"") | D7: =IFERROR(AVERAGE('Results Input'!M204,'Results Input'!M205,'Results Input'!M206,'Results Input'!M207,'Results Input'!M208,'Results Input'!M209,'Results Input'!M210,'Results Input'!M211,'Results Input'!M212,'Results Input'!M213,'Results Input'!M214,'Results Input'!M215,'Results Input'!M216,'Results Input'!M217,'Results Input'!M218,'Results Input'!M219,'Results Input'!M220,'Results Input'!M221,'Results Input'!M222,'Results Input'!M223,'Results Input'!M224,'Results Input'!M225,'Results Input'!M226,'Results Input'!M227,'Results Input'!M228),"") | E7: =IFERROR(AVERAGE('Results Input'!N204,'Results Input'!N205,'Results Input'!N206,'Results Input'!N207,'Results Input'!N208,'Results Input'!N209,'Results Input'!N210,'Results Input'!N211,'Results Input'!N212,'Results Input'!N213,'Results Input'!N214,'Results Input'!N215,'Results Input'!N216,'Results Input'!N217,'Results Input'!N218,'Results Input'!N219,'Results Input'!N220,'Results Input'!N221,'Results Input'!N222,'Results Input'!N223,'Results Input'!N224,'Results Input'!N225,'Results Input'!N226,'Results Input'!N227,'Results Input'!N228),"") | F7: =IFERROR(AVERAGE('Results Input'!Q204,'Results Input'!Q205,'Results Input'!Q206,'Results Input'!Q207,'Results Input'!Q208,'Results Input'!Q209,'Results Input'!Q210,'Results Input'!Q211,'Results Input'!Q212,'Results Input'!Q213,'Results Input'!Q214,'Results Input'!Q215,'Results Input'!Q216,'Results Input'!Q217,'Results Input'!Q218,'Results Input'!Q219,'Results Input'!Q220,'Results Input'!Q221,'Results Input'!Q222,'Results Input'!Q223,'Results Input'!Q224,'Results Input'!Q225,'Results Input'!Q226,'Results Input'!Q227,'Results Input'!Q228),"") | G7: =IFERROR(AVERAGE('Results Input'!R204,'Results Input'!R205,'Results Input'!R206,'Results Input'!R207,'Results Input'!R208,'Results Input'!R209,'Results Input'!R210,'Results Input'!R211,'Results Input'!R212,'Results Input'!R213,'Results Input'!R214,'Results Input'!R215,'Results Input'!R216,'Results Input'!R217,'Results Input'!R218,'Results Input'!R219,'Results Input'!R220,'Results Input'!R221,'Results Input'!R222,'Results Input'!R223,'Results Input'!R224,'Results Input'!R225,'Results Input'!R226,'Results Input'!R227,'Results Input'!R228),"")
A8: Adv RAG + LlamaIndex | B8: =IFERROR(AVERAGE('Results Input'!K304,'Results Input'!K305,'Results Input'!K306,'Results Input'!K307,'Results Input'!K308,'Results Input'!K309,'Results Input'!K310,'Results Input'!K311,'Results Input'!K312,'Results Input'!K313,'Results Input'!K314,'Results Input'!K315,'Results Input'!K316,'Results Input'!K317,'Results Input'!K318,'Results Input'!K319,'Results Input'!K320,'Results Input'!K321,'Results Input'!K322,'Results Input'!K323,'Results Input'!K324,'Results Input'!K325,'Results Input'!K326,'Results Input'!K327,'Results Input'!K328),"") | C8: =IFERROR(AVERAGE('Results Input'!L304,'Results Input'!L305,'Results Input'!L306,'Results Input'!L307,'Results Input'!L308,'Results Input'!L309,'Results Input'!L310,'Results Input'!L311,'Results Input'!L312,'Results Input'!L313,'Results Input'!L314,'Results Input'!L315,'Results Input'!L316,'Results Input'!L317,'Results Input'!L318,'Results Input'!L319,'Results Input'!L320,'Results Input'!L321,'Results Input'!L322,'Results Input'!L323,'Results Input'!L324,'Results Input'!L325,'Results Input'!L326,'Results Input'!L327,'Results Input'!L328),"") | D8: =IFERROR(AVERAGE('Results Input'!M304,'Results Input'!M305,'Results Input'!M306,'Results Input'!M307,'Results Input'!M308,'Results Input'!M309,'Results Input'!M310,'Results Input'!M311,'Results Input'!M312,'Results Input'!M313,'Results Input'!M314,'Results Input'!M315,'Results Input'!M316,'Results Input'!M317,'Results Input'!M318,'Results Input'!M319,'Results Input'!M320,'Results Input'!M321,'Results Input'!M322,'Results Input'!M323,'Results Input'!M324,'Results Input'!M325,'Results Input'!M326,'Results Input'!M327,'Results Input'!M328),"") | E8: =IFERROR(AVERAGE('Results Input'!N304,'Results Input'!N305,'Results Input'!N306,'Results Input'!N307,'Results Input'!N308,'Results Input'!N309,'Results Input'!N310,'Results Input'!N311,'Results Input'!N312,'Results Input'!N313,'Results Input'!N314,'Results Input'!N315,'Results Input'!N316,'Results Input'!N317,'Results Input'!N318,'Results Input'!N319,'Results Input'!N320,'Results Input'!N321,'Results Input'!N322,'Results Input'!N323,'Results Input'!N324,'Results Input'!N325,'Results Input'!N326,'Results Input'!N327,'Results Input'!N328),"") | F8: =IFERROR(AVERAGE('Results Input'!Q304,'Results Input'!Q305,'Results Input'!Q306,'Results Input'!Q307,'Results Input'!Q308,'Results Input'!Q309,'Results Input'!Q310,'Results Input'!Q311,'Results Input'!Q312,'Results Input'!Q313,'Results Input'!Q314,'Results Input'!Q315,'Results Input'!Q316,'Results Input'!Q317,'Results Input'!Q318,'Results Input'!Q319,'Results Input'!Q320,'Results Input'!Q321,'Results Input'!Q322,'Results Input'!Q323,'Results Input'!Q324,'Results Input'!Q325,'Results Input'!Q326,'Results Input'!Q327,'Results Input'!Q328),"") | G8: =IFERROR(AVERAGE('Results Input'!R304,'Results Input'!R305,'Results Input'!R306,'Results Input'!R307,'Results Input'!R308,'Results Input'!R309,'Results Input'!R310,'Results Input'!R311,'Results Input'!R312,'Results Input'!R313,'Results Input'!R314,'Results Input'!R315,'Results Input'!R316,'Results Input'!R317,'Results Input'!R318,'Results Input'!R319,'Results Input'!R320,'Results Input'!R321,'Results Input'!R322,'Results Input'!R323,'Results Input'!R324,'Results Input'!R325,'Results Input'!R326,'Results Input'!R327,'Results Input'!R328),"")
A10: PARAPHRASED (25 questions — form 10-K & 10-Q)
A11: System | B11: Faithfulness | C11: Ans Relevancy | D11: Hallucination↓ | E11: F1 Token | F11: Task Completion | G11: Accuracy
